在其他语言中错误处理一般使用try...catch...finally，在Go中没有这种机制，Go提供了defer、panic、recover来处理错误。

### error

Go提供了两种创建error的方法：**errors.New**和**fmt.Errorf**
```
  package main

  import (
    "errors"
    "fmt"
  )

  // 求倒数
  func reciprocal(n int) (float64, error) {
    if n == 0 {
      return 0, errors.New("0不能求倒数")
    }
    return float64(1) / float64(n), nil
  }

  func main() {
    for i := 3; i >=0; i-- {
      ret, err := reciprocal(i)
      if err != nil {
        fmt.Println(err)
      } else {
        fmt.Printf("1/%d = %.3f\n", i, ret)
      }
    }
  }
```

### panic

panic一般和defer、recover进场一起出现，用于异常处理。
```
package main

import "fmt"

func doPanic() {
  err := recover() // recover不会Panic异常
  if err != nil {
    fmt.Println("doPanic()捕获到异常:", err)
  }
}

func main() {
  // 注册捕获异常的处理函数
  defer doPanic()
  n := 0
  ret := 1 / n // 抛出panic异常

  fmt.Println("main ret = ", ret)
}
```
panic会在抛出它的函数中向自己和所有上层抛出，如果到最顶层还没recover将器捕获，那么程序就会崩溃；如果在某一层defer注册的函数被recover捕获，那么被注册的函数就将获得程序控制权，进行异常处理。